Workbook

Sheet Read Me
A1: Torrent collection breakdown — 2026-08-27
A3: Facts only, per your note: no projections or model numbers anywhere in this workbook.
A4: Sources: your collection export of 8/27 (prices, variant + active flags, release dates) and the fresh pt_card_list of 8/27 (LE identification, new-wave prices).
A6: Sheets:
A7: Matrix — counts of your variants, LEs, and 5,000+ BUY cards by tier and position (live COUNTIFS over the detail sheets).
A8: Variants — all 75 variant cards you own.
A9: LEs — all 21 limited editions you own (incl. two from the new wave).
A10: Buy over 5000 — your 100 cards with a standing bid above 5,000 points.
A11: New LE Wave — all 37 cards released Aug 23–25 (22 of them LE), with an Owned flag; 10 are already yours.
A13: Definitions:
A14: L10 = average of the last 10 sales (market value). BUY = highest standing bid — what you receive selling instantly.
A15: Ask (New LE Wave) = lowest current listing — what it costs to buy right now; 0/blank = none listed.
... A17: Active = on your current tournament roster in the 8/27 export.

Sheet Matrix
A1: Your VARIANTS by tier × position
A2: Tier | B2: C | C2: 1B | D2: 2B | E2: 3B | F2: SS | G2: LF | H2: CF | I2: RF | J2: DH | K2: SP | L2: RP | M2: CL | N2: Total
A3: Iron | B3: =COUNTIFS(Variants!$B:$B,$A3,Variants!$C:$C,B$2) -> 3 | C3: =COUNTIFS(Variants!$B:$B,$A3,Variants!$C:$C,C$2) -> 0 | D3: =COUNTIFS(Variants!$B:$B,$A3,Variants!$C:$C,D$2) -> 3 | E3: =COUNTIFS(Variants!$B:$B,$A3,Variants!$C:$C,E$2) -> 0 | F3: =COUNTIFS(Variants!$B:$B,$A3,Variants!$C:$C,F$2) -> 0 | G3: =COUNTIFS(Variants!$B:$B,$A3,Variants!$C:$C,G$2) -> 1 | H3: =COUNTIFS(Variants!$B:$B,$A3,Variants!$C:$C,H$2) -> 2 | I3: =COUNTIFS(Variants!$B:$B,$A3,Variants!$C:$C,I$2) -> 1 | ... M3: =COUNTIFS(Variants!$B:$B,$A3,Variants!$C:$C,M$2) -> 2 | N3: =SUM(B3:M3) -> 15
A4: Bronze | B4: =COUNTIFS(Variants!$B:$B,$A4,Variants!$C:$C,B$2) -> 2 | C4: =COUNTIFS(Variants!$B:$B,$A4,Variants!$C:$C,C$2) -> 1 | D4: =COUNTIFS(Variants!$B:$B,$A4,Variants!$C:$C,D$2) -> 1 | E4: =COUNTIFS(Variants!$B:$B,$A4,Variants!$C:$C,E$2) -> 0 | F4: =COUNTIFS(Variants!$B:$B,$A4,Variants!$C:$C,F$2) -> 1 | G4: =COUNTIFS(Variants!$B:$B,$A4,Variants!$C:$C,G$2) -> 1 | H4: =COUNTIFS(Variants!$B:$B,$A4,Variants!$C:$C,H$2) -> 1 | I4: =COUNTIFS(Variants!$B:$B,$A4,Variants!$C:$C,I$2) -> 1 | ... M4: =COUNTIFS(Variants!$B:$B,$A4,Variants!$C:$C,M$2) -> 1 | N4: =SUM(B4:M4) -> 12
A5: Silver | B5: =COUNTIFS(Variants!$B:$B,$A5,Variants!$C:$C,B$2) -> 1 | C5: =COUNTIFS(Variants!$B:$B,$A5,Variants!$C:$C,C$2) -> 3 | D5: =COUNTIFS(Variants!$B:$B,$A5,Variants!$C:$C,D$2) -> 1 | E5: =COUNTIFS(Variants!$B:$B,$A5,Variants!$C:$C,E$2) -> 3 | F5: =COUNTIFS(Variants!$B:$B,$A5,Variants!$C:$C,F$2) -> 1 | G5: =COUNTIFS(Variants!$B:$B,$A5,Variants!$C:$C,G$2) -> 2 | H5: =COUNTIFS(Variants!$B:$B,$A5,Variants!$C:$C,H$2) -> 0 | I5: =COUNTIFS(Variants!$B:$B,$A5,Variants!$C:$C,I$2) -> 2 | ... M5: =COUNTIFS(Variants!$B:$B,$A5,Variants!$C:$C,M$2) -> 0 | N5: =SUM(B5:M5) -> 20
A6: Gold | B6: =COUNTIFS(Variants!$B:$B,$A6,Variants!$C:$C,B$2) -> 2 | C6: =COUNTIFS(Variants!$B:$B,$A6,Variants!$C:$C,C$2) -> 1 | D6: =COUNTIFS(Variants!$B:$B,$A6,Variants!$C:$C,D$2) -> 3 | E6: =COUNTIFS(Variants!$B:$B,$A6,Variants!$C:$C,E$2) -> 1 | F6: =COUNTIFS(Variants!$B:$B,$A6,Variants!$C:$C,F$2) -> 1 | G6: =COUNTIFS(Variants!$B:$B,$A6,Variants!$C:$C,G$2) -> 1 | H6: =COUNTIFS(Variants!$B:$B,$A6,Variants!$C:$C,H$2) -> 0 | I6: =COUNTIFS(Variants!$B:$B,$A6,Variants!$C:$C,I$2) -> 2 | ... M6: =COUNTIFS(Variants!$B:$B,$A6,Variants!$C:$C,M$2) -> 2 | N6: =SUM(B6:M6) -> 17
A7: Diamond | B7: =COUNTIFS(Variants!$B:$B,$A7,Variants!$C:$C,B$2) -> 0 | C7: =COUNTIFS(Variants!$B:$B,$A7,Variants!$C:$C,C$2) -> 1 | D7: =COUNTIFS(Variants!$B:$B,$A7,Variants!$C:$C,D$2) -> 1 | E7: =COUNTIFS(Variants!$B:$B,$A7,Variants!$C:$C,E$2) -> 0 | F7: =COUNTIFS(Variants!$B:$B,$A7,Variants!$C:$C,F$2) -> 2 | G7: =COUNTIFS(Variants!$B:$B,$A7,Variants!$C:$C,G$2) -> 2 | H7: =COUNTIFS(Variants!$B:$B,$A7,Variants!$C:$C,H$2) -> 1 | I7: =COUNTIFS(Variants!$B:$B,$A7,Variants!$C:$C,I$2) -> 0 | ... M7: =COUNTIFS(Variants!$B:$B,$A7,Variants!$C:$C,M$2) -> 0 | N7: =SUM(B7:M7) -> 10
A8: Perfect | B8: =COUNTIFS(Variants!$B:$B,$A8,Variants!$C:$C,B$2) -> 1 | C8: =COUNTIFS(Variants!$B:$B,$A8,Variants!$C:$C,C$2) -> 0 | D8: =COUNTIFS(Variants!$B:$B,$A8,Variants!$C:$C,D$2) -> 0 | E8: =COUNTIFS(Variants!$B:$B,$A8,Variants!$C:$C,E$2) -> 0 | F8: =COUNTIFS(Variants!$B:$B,$A8,Variants!$C:$C,F$2) -> 0 | G8: =COUNTIFS(Variants!$B:$B,$A8,Variants!$C:$C,G$2) -> 0 | H8: =COUNTIFS(Variants!$B:$B,$A8,Variants!$C:$C,H$2) -> 0 | I8: =COUNTIFS(Variants!$B:$B,$A8,Variants!$C:$C,I$2) -> 0 | ... M8: =COUNTIFS(Variants!$B:$B,$A8,Variants!$C:$C,M$2) -> 0 | N8: =SUM(B8:M8) -> 1
A9: Total | B9: =SUM(B3:B8) -> 9 | C9: =SUM(C3:C8) -> 6 | D9: =SUM(D3:D8) -> 9 | E9: =SUM(E3:E8) -> 4 | F9: =SUM(F3:F8) -> 5 | G9: =SUM(G3:G8) -> 7 | H9: =SUM(H3:H8) -> 4 | I9: =SUM(I3:I8) -> 6 | ... N9: =SUM(N3:N8) -> 75
A12: Your LIMITED EDITIONS by tier × position
A13: Tier | B13: C | C13: 1B | D13: 2B | E13: 3B | F13: SS | G13: LF | H13: CF | I13: RF | J13: DH | K13: SP | L13: RP | M13: CL | N13: Total
A14: Iron | B14: =COUNTIFS(LEs!$B:$B,$A14,LEs!$C:$C,B$13) -> 0 | C14: =COUNTIFS(LEs!$B:$B,$A14,LEs!$C:$C,C$13) -> 1 | D14: =COUNTIFS(LEs!$B:$B,$A14,LEs!$C:$C,D$13) -> 0 | E14: =COUNTIFS(LEs!$B:$B,$A14,LEs!$C:$C,E$13) -> 0 | F14: =COUNTIFS(LEs!$B:$B,$A14,LEs!$C:$C,F$13) -> 0 | G14: =COUNTIFS(LEs!$B:$B,$A14,LEs!$C:$C,G$13) -> 0 | H14: =COUNTIFS(LEs!$B:$B,$A14,LEs!$C:$C,H$13) -> 0 | I14: =COUNTIFS(LEs!$B:$B,$A14,LEs!$C:$C,I$13) -> 0 | ... M14: =COUNTIFS(LEs!$B:$B,$A14,LEs!$C:$C,M$13) -> 0 | N14: =SUM(B14:M14) -> 2
A15: Bronze | B15: =COUNTIFS(LEs!$B:$B,$A15,LEs!$C:$C,B$13) -> 0 | C15: =COUNTIFS(LEs!$B:$B,$A15,LEs!$C:$C,C$13) -> 0 | D15: =COUNTIFS(LEs!$B:$B,$A15,LEs!$C:$C,D$13) -> 0 | E15: =COUNTIFS(LEs!$B:$B,$A15,LEs!$C:$C,E$13) -> 1 | F15: =COUNTIFS(LEs!$B:$B,$A15,LEs!$C:$C,F$13) -> 0 | G15: =COUNTIFS(LEs!$B:$B,$A15,LEs!$C:$C,G$13) -> 0 | H15: =COUNTIFS(LEs!$B:$B,$A15,LEs!$C:$C,H$13) -> 1 | I15: =COUNTIFS(LEs!$B:$B,$A15,LEs!$C:$C,I$13) -> 0 | ... M15: =COUNTIFS(LEs!$B:$B,$A15,LEs!$C:$C,M$13) -> 1 | N15: =SUM(B15:M15) -> 6
A16: Silver | B16: =COUNTIFS(LEs!$B:$B,$A16,LEs!$C:$C,B$13) -> 0 | C16: =COUNTIFS(LEs!$B:$B,$A16,LEs!$C:$C,C$13) -> 0 | D16: =COUNTIFS(LEs!$B:$B,$A16,LEs!$C:$C,D$13) -> 1 | E16: =COUNTIFS(LEs!$B:$B,$A16,LEs!$C:$C,E$13) -> 1 | F16: =COUNTIFS(LEs!$B:$B,$A16,LEs!$C:$C,F$13) -> 0 | G16: =COUNTIFS(LEs!$B:$B,$A16,LEs!$C:$C,G$13) -> 0 | H16: =COUNTIFS(LEs!$B:$B,$A16,LEs!$C:$C,H$13) -> 1 | I16: =COUNTIFS(LEs!$B:$B,$A16,LEs!$C:$C,I$13) -> 1 | ... M16: =COUNTIFS(LEs!$B:$B,$A16,LEs!$C:$C,M$13) -> 1 | N16: =SUM(B16:M16) -> 6
A17: Gold | B17: =COUNTIFS(LEs!$B:$B,$A17,LEs!$C:$C,B$13) -> 0 | C17: =COUNTIFS(LEs!$B:$B,$A17,LEs!$C:$C,C$13) -> 0 | D17: =COUNTIFS(LEs!$B:$B,$A17,LEs!$C:$C,D$13) -> 0 | E17: =COUNTIFS(LEs!$B:$B,$A17,LEs!$C:$C,E$13) -> 0 | F17: =COUNTIFS(LEs!$B:$B,$A17,LEs!$C:$C,F$13) -> 0 | G17: =COUNTIFS(LEs!$B:$B,$A17,LEs!$C:$C,G$13) -> 0 | H17: =COUNTIFS(LEs!$B:$B,$A17,LEs!$C:$C,H$13) -> 0 | I17: =COUNTIFS(LEs!$B:$B,$A17,LEs!$C:$C,I$13) -> 1 | ... M17: =COUNTIFS(LEs!$B:$B,$A17,LEs!$C:$C,M$13) -> 0 | N17: =SUM(B17:M17) -> 4
A18: Diamond | B18: =COUNTIFS(LEs!$B:$B,$A18,LEs!$C:$C,B$13) -> 0 | C18: =COUNTIFS(LEs!$B:$B,$A18,LEs!$C:$C,C$13) -> 0 | D18: =COUNTIFS(LEs!$B:$B,$A18,LEs!$C:$C,D$13) -> 1 | E18: =COUNTIFS(LEs!$B:$B,$A18,LEs!$C:$C,E$13) -> 0 | F18: =COUNTIFS(LEs!$B:$B,$A18,LEs!$C:$C,F$13) -> 0 | G18: =COUNTIFS(LEs!$B:$B,$A18,LEs!$C:$C,G$13) -> 1 | H18: =COUNTIFS(LEs!$B:$B,$A18,LEs!$C:$C,H$13) -> 0 | I18: =COUNTIFS(LEs!$B:$B,$A18,LEs!$C:$C,I$13) -> 0 | ... M18: =COUNTIFS(LEs!$B:$B,$A18,LEs!$C:$C,M$13) -> 0 | N18: =SUM(B18:M18) -> 3
A19: Perfect | B19: =COUNTIFS(LEs!$B:$B,$A19,LEs!$C:$C,B$13) -> 0 | C19: =COUNTIFS(LEs!$B:$B,$A19,LEs!$C:$C,C$13) -> 0 | D19: =COUNTIFS(LEs!$B:$B,$A19,LEs!$C:$C,D$13) -> 0 | E19: =COUNTIFS(LEs!$B:$B,$A19,LEs!$C:$C,E$13) -> 0 | F19: =COUNTIFS(LEs!$B:$B,$A19,LEs!$C:$C,F$13) -> 0 | G19: =COUNTIFS(LEs!$B:$B,$A19,LEs!$C:$C,G$13) -> 0 | H19: =COUNTIFS(LEs!$B:$B,$A19,LEs!$C:$C,H$13) -> 0 | I19: =COUNTIFS(LEs!$B:$B,$A19,LEs!$C:$C,I$13) -> 0 | ... M19: =COUNTIFS(LEs!$B:$B,$A19,LEs!$C:$C,M$13) -> 0 | N19: =SUM(B19:M19) -> 0
A20: Total | B20: =SUM(B14:B19) -> 0 | C20: =SUM(C14:C19) -> 1 | D20: =SUM(D14:D19) -> 2 | E20: =SUM(E14:E19) -> 2 | F20: =SUM(F14:F19) -> 0 | G20: =SUM(G14:G19) -> 1 | H20: =SUM(H14:H19) -> 2 | I20: =SUM(I14:I19) -> 2 | ... N20: =SUM(N14:N19) -> 21
A23: Your cards with BUY > 5,000 by tier × position
A24: Tier | B24: C | C24: 1B | D24: 2B | E24: 3B | F24: SS | G24: LF | H24: CF | I24: RF | J24: DH | K24: SP | L24: RP | M24: CL | N24: Total
A25: Iron | B25: =COUNTIFS('Buy over 5000'!$B:$B,$A25,'Buy over 5000'!$C:$C,B$24) -> 0 | C25: =COUNTIFS('Buy over 5000'!$B:$B,$A25,'Buy over 5000'!$C:$C,C$24) -> 0 | D25: =COUNTIFS('Buy over 5000'!$B:$B,$A25,'Buy over 5000'!$C:$C,D$24) -> 0 | E25: =COUNTIFS('Buy over 5000'!$B:$B,$A25,'Buy over 5000'!$C:$C,E$24) -> 0 | F25: =COUNTIFS('Buy over 5000'!$B:$B,$A25,'Buy over 5000'!$C:$C,F$24) -> 0 | G25: =COUNTIFS('Buy over 5000'!$B:$B,$A25,'Buy over 5000'!$C:$C,G$24) -> 0 | H25: =COUNTIFS('Buy over 5000'!$B:$B,$A25,'Buy over 5000'!$C:$C,H$24) -> 0 | I25: =COUNTIFS('Buy over 5000'!$B:$B,$A25,'Buy over 5000'!$C:$C,I$24) -> 0 | ... M25: =COUNTIFS('Buy over 5000'!$B:$B,$A25,'Buy over 5000'!$C:$C,M$24) -> 0 | N25: =SUM(B25:M25) -> 2
A26: Bronze | B26: =COUNTIFS('Buy over 5000'!$B:$B,$A26,'Buy over 5000'!$C:$C,B$24) -> 0 | C26: =COUNTIFS('Buy over 5000'!$B:$B,$A26,'Buy over 5000'!$C:$C,C$24) -> 1 | D26: =COUNTIFS('Buy over 5000'!$B:$B,$A26,'Buy over 5000'!$C:$C,D$24) -> 0 | E26: =COUNTIFS('Buy over 5000'!$B:$B,$A26,'Buy over 5000'!$C:$C,E$24) -> 1 | F26: =COUNTIFS('Buy over 5000'!$B:$B,$A26,'Buy over 5000'!$C:$C,F$24) -> 0 | G26: =COUNTIFS('Buy over 5000'!$B:$B,$A26,'Buy over 5000'!$C:$C,G$24) -> 1 | H26: =COUNTIFS('Buy over 5000'!$B:$B,$A26,'Buy over 5000'!$C:$C,H$24) -> 0 | I26: =COUNTIFS('Buy over 5000'!$B:$B,$A26,'Buy over 5000'!$C:$C,I$24) -> 0 | ... M26: =COUNTIFS('Buy over 5000'!$B:$B,$A26,'Buy over 5000'!$C:$C,M$24) -> 1 | N26: =SUM(B26:M26) -> 4
A27: Silver | B27: =COUNTIFS('Buy over 5000'!$B:$B,$A27,'Buy over 5000'!$C:$C,B$24) -> 0 | C27: =COUNTIFS('Buy over 5000'!$B:$B,$A27,'Buy over 5000'!$C:$C,C$24) -> 0 | D27: =COUNTIFS('Buy over 5000'!$B:$B,$A27,'Buy over 5000'!$C:$C,D$24) -> 0 | E27: =COUNTIFS('Buy over 5000'!$B:$B,$A27,'Buy over 5000'!$C:$C,E$24) -> 1 | F27: =COUNTIFS('Buy over 5000'!$B:$B,$A27,'Buy over 5000'!$C:$C,F$24) -> 1 | G27: =COUNTIFS('Buy over 5000'!$B:$B,$A27,'Buy over 5000'!$C:$C,G$24) -> 0 | H27: =COUNTIFS('Buy over 5000'!$B:$B,$A27,'Buy over 5000'!$C:$C,H$24) -> 1 | I27: =COUNTIFS('Buy over 5000'!$B:$B,$A27,'Buy over 5000'!$C:$C,I$24) -> 1 | ... M27: =COUNTIFS('Buy over 5000'!$B:$B,$A27,'Buy over 5000'!$C:$C,M$24) -> 2 | N27: =SUM(B27:M27) -> 7
A28: Gold | B28: =COUNTIFS('Buy over 5000'!$B:$B,$A28,'Buy over 5000'!$C:$C,B$24) -> 0 | C28: =COUNTIFS('Buy over 5000'!$B:$B,$A28,'Buy over 5000'!$C:$C,C$24) -> 0 | D28: =COUNTIFS('Buy over 5000'!$B:$B,$A28,'Buy over 5000'!$C:$C,D$24) -> 0 | E28: =COUNTIFS('Buy over 5000'!$B:$B,$A28,'Buy over 5000'!$C:$C,E$24) -> 0 | F28: =COUNTIFS('Buy over 5000'!$B:$B,$A28,'Buy over 5000'!$C:$C,F$24) -> 1 | G28: =COUNTIFS('Buy over 5000'!$B:$B,$A28,'Buy over 5000'!$C:$C,G$24) -> 0 | H28: =COUNTIFS('Buy over 5000'!$B:$B,$A28,'Buy over 5000'!$C:$C,H$24) -> 2 | I28: =COUNTIFS('Buy over 5000'!$B:$B,$A28,'Buy over 5000'!$C:$C,I$24) -> 1 | ... M28: =COUNTIFS('Buy over 5000'!$B:$B,$A28,'Buy over 5000'!$C:$C,M$24) -> 0 | N28: =SUM(B28:M28) -> 8
A29: Diamond | B29: =COUNTIFS('Buy over 5000'!$B:$B,$A29,'Buy over 5000'!$C:$C,B$24) -> 1 | C29: =COUNTIFS('Buy over 5000'!$B:$B,$A29,'Buy over 5000'!$C:$C,C$24) -> 3 | D29: =COUNTIFS('Buy over 5000'!$B:$B,$A29,'Buy over 5000'!$C:$C,D$24) -> 1 | E29: =COUNTIFS('Buy over 5000'!$B:$B,$A29,'Buy over 5000'!$C:$C,E$24) -> 2 | F29: =COUNTIFS('Buy over 5000'!$B:$B,$A29,'Buy over 5000'!$C:$C,F$24) -> 9 | G29: =COUNTIFS('Buy over 5000'!$B:$B,$A29,'Buy over 5000'!$C:$C,G$24) -> 2 | H29: =COUNTIFS('Buy over 5000'!$B:$B,$A29,'Buy over 5000'!$C:$C,H$24) -> 3 | I29: =COUNTIFS('Buy over 5000'!$B:$B,$A29,'Buy over 5000'!$C:$C,I$24) -> 3 | ... M29: =COUNTIFS('Buy over 5000'!$B:$B,$A29,'Buy over 5000'!$C:$C,M$24) -> 2 | N29: =SUM(B29:M29) -> 41
A30: Perfect | B30: =COUNTIFS('Buy over 5000'!$B:$B,$A30,'Buy over 5000'!$C:$C,B$24) -> 1 | C30: =COUNTIFS('Buy over 5000'!$B:$B,$A30,'Buy over 5000'!$C:$C,C$24) -> 2 | D30: =COUNTIFS('Buy over 5000'!$B:$B,$A30,'Buy over 5000'!$C:$C,D$24) -> 3 | E30: =COUNTIFS('Buy over 5000'!$B:$B,$A30,'Buy over 5000'!$C:$C,E$24) -> 3 | F30: =COUNTIFS('Buy over 5000'!$B:$B,$A30,'Buy over 5000'!$C:$C,F$24) -> 2 | G30: =COUNTIFS('Buy over 5000'!$B:$B,$A30,'Buy over 5000'!$C:$C,G$24) -> 1 | H30: =COUNTIFS('Buy over 5000'!$B:$B,$A30,'Buy over 5000'!$C:$C,H$24) -> 1 | I30: =COUNTIFS('Buy over 5000'!$B:$B,$A30,'Buy over 5000'!$C:$C,I$24) -> 3 | ... M30: =COUNTIFS('Buy over 5000'!$B:$B,$A30,'Buy over 5000'!$C:$C,M$24) -> 5 | N30: =SUM(B30:M30) -> 38
A31: Total | B31: =SUM(B25:B30) -> 2 | C31: =SUM(C25:C30) -> 6 | D31: =SUM(D25:D30) -> 4 | E31: =SUM(E25:E30) -> 7 | F31: =SUM(F25:F30) -> 13 | G31: =SUM(G25:G30) -> 4 | H31: =SUM(H25:H30) -> 7 | I31: =SUM(I25:I30) -> 8 | ... N31: =SUM(N25:N30) -> 100

Sheet Variants
A1: Name | B1: Tier | C1: Pos | D1: VAL | E1: Released | F1: L10 | G1: BUY | H1: Active | I1: Variant | J1: SubType
A2: Jack Shepard | B2: Iron | C2: C | D2: 56 | E2: 2026-03-13 | F2: 362 | G2: 0 | H2: No | I2: Y
A3: Billy Bryan | B3: Iron | C3: C | D3: 48 | E3: 2026-06-25 | F3: 596 | G3: 0 | H3: No | I3: Y
A4: Jonathan Lucroy | B4: Iron | C4: C | D4: 48 | E4: 2026-05-12 | F4: 6317 | G4: 0 | H4: No | I4: Y
A5: Brice Turang | B5: Iron | C5: 2B | D5: 55 | E5: 2026-03-13 | F5: 252 | G5: 0 | H5: No | I5: Y
A6: Derek Dietrich | B6: Iron | C6: 2B | D6: 51 | E6: 2026-05-07 | F6: 2344 | G6: 0 | H6: No | I6: Y | J6: BBR
A7: Tsung-Che Cheng | B7: Iron | C7: 2B | D7: 44 | E7: 2026-03-19 | F7: 6096 | G7: 0 | H7: No | I7: Y | J7: WBC
A8: Taylor Ward | B8: Iron | C8: LF | D8: 58 | E8: 2026-03-13 | F8: 203 | G8: 0 | H8: No | I8: Y
A9: Buster Adams | B9: Iron | C9: CF | D9: 57 | E9: 2026-03-13 | F9: 182 | G9: 0 | H9: No | I9: Y
A10: Mike Trout | B10: Iron | C10: CF | D10: 51 | E10: 2026-04-09 | F10: 239 | G10: 0 | H10: No | I10: Y | J10: BBR
A11: Grady Sizemore | B11: Iron | C11: RF | D11: 53 | E11: 2026-05-14 | F11: 9465 | G11: 0 | H11: No | I11: Y
A12: Ramon Arano | B12: Iron | C12: SP | D12: 55 | E12: 2026-03-13 | F12: 415 | G12: 0 | H12: No | I12: Y
A13: Isidro Fabre | B13: Iron | C13: SP | D13: 51 | E13: 2026-03-13 | F13: 164 | G13: 0 | H13: No | I13: Y
A14: Don August | B14: Iron | C14: SP | D14: 50 | E14: 2026-08-09 | F14: 15044 | G14: 0 | H14: No | I14: Y | J14: BBR
A15: Trevor Rosenthal | B15: Iron | C15: CL | D15: 53 | E15: 2026-05-21 | F15: 592 | G15: 0 | H15: No | I15: Y
A16: Al Holland | B16: Iron | C16: CL | D16: 47 | E16: 2026-07-09 | F16: 10140 | G16: 0 | H16: No | I16: Y | J16: BBR
A17: Thayron Liranzo | B17: Bronze | C17: C | D17: 65 | E17: 2026-08-13 | F17: 21001 | G17: 0 | H17: No | I17: Y
A18: Buck Martinez | B18: Bronze | C18: C | D18: 63 | E18: 2026-06-19 | F18: 7739 | G18: 0 | H18: No | I18: Y
A19: Mickey Mantle | B19: Bronze | C19: 1B | D19: 68 | E19: 2026-04-23 | F19: 1823 | G19: 0 | H19: No | I19: Y
A20: Marco Scutaro | B20: Bronze | C20: 2B | D20: 69 | E20: 2026-07-30 | F20: 128885 | G20: 0 | H20: No | I20: Y | J20: BBR
A21: Ketel Marte | B21: Bronze | C21: SS | D21: 68 | E21: 2026-03-13 | F21: 2043 | G21: 0 | H21: No | I21: Y
A22: Rickey Henderson | B22: Bronze | C22: LF | D22: 68 | E22: 2026-05-14 | F22: 11445 | G22: 0 | H22: No | I22: Y
A23: Brett Butler | B23: Bronze | C23: CF | D23: 64 | E23: 2026-07-02 | F23: 14468 | G23: 0 | H23: No | I23: Y | J23: BBR
A24: Ed Morgan | B24: Bronze | C24: RF | D24: 66 | E24: 2026-07-02 | F24: 129845 | G24: 0 | H24: No | I24: Y | J24: BBR
A25: Happy Townsend | B25: Bronze | C25: SP | D25: 63 | E25: 2026-03-13 | F25: 274 | G25: 0 | H25: No | I25: Y
A26: Chuck Finley | B26: Bronze | C26: SP | D26: 60 | E26: 2026-05-12 | F26: 3957 | G26: 0 | H26: No | I26: Y
A27: Adam Cimber | B27: Bronze | C27: RP | D27: 69 | E27: 2026-03-13 | F27: 9120 | G27: 0 | H27: No | I27: Y
A28: Marshall Bridges | B28: Bronze | C28: CL | D28: 65 | E28: 2026-03-13 | F28: 1933 | G28: 0 | H28: No | I28: Y
A29: Nathan Flewelling | B29: Silver | C29: C | D29: 75 | E29: 2026-07-14 | F29: 9450 | G29: 0 | H29: No | I29: Y
A30: Will Clark | B30: Silver | C30: 1B | D30: 78 | E30: 2026-06-23 | F30: 3545 | G30: 0 | H30: No | I30: Y
A31: Vic Power | B31: Silver | C31: 1B | D31: 76 | E31: 2026-06-04 | F31: 21592 | G31: 0 | H31: No | I31: Y | J31: UTIL
A32: Nick Swisher | B32: Silver | C32: 1B | D32: 70 | E32: 2026-06-18 | F32: 5090 | G32: 0 | H32: No | I32: Y
A33: Jose Vidro | B33: Silver | C33: 2B | D33: 77 | E33: 2026-05-26 | F33: 11423 | G33: 0 | H33: No | I33: Y
A34: Justin Turner | B34: Silver | C34: 3B | D34: 78 | E34: 2026-04-30 | F34: 6645 | G34: 0 | H34: No | I34: Y
A35: Dave Hollins | B35: Silver | C35: 3B | D35: 73 | E35: 2026-05-07 | F35: 2819 | G35: 0 | H35: No | I35: Y | J35: BBR
A36: Fernando Tatis | B36: Silver | C36: 3B | D36: 73 | E36: 2026-06-18 | F36: 6915 | G36: 0 | H36: No | I36: Y
A37: Ozzie Smith | B37: Silver | C37: SS | D37: 79 | E37: 2026-06-09 | F37: 12101 | G37: 0 | H37: No | I37: Y | J37: HOF
A38: Chuck Essegian | B38: Silver | C38: LF | D38: 74 | E38: 2026-05-07 | F38: 2513 | G38: 0 | H38: No | I38: Y | J38: BBR
A39: Jimmie Lyons | B39: Silver | C39: LF | D39: 72 | E39: 2026-03-13 | F39: 684 | G39: 0 | H39: No | I39: Y
A40: Owen Caissie | B40: Silver | C40: RF | D40: 78 | E40: 2026-04-02 | F40: 16222 | G40: 0 | H40: No | I40: Y
...

Sheet LEs
A1: Name | B1: Tier | C1: Pos | D1: VAL | E1: Released | F1: L10 | G1: BUY | H1: Active | I1: Variant | J1: SubType
A2: Andres Galarraga | B2: Iron | C2: 1B | D2: 59 | E2: 2026-06-02 | F2: 27402 | G2: 234 | H2: No | I2: N | J2: LE
A3: Nathan Eovaldi | B3: Iron | C3: SP | D3: 59 | E3: 2026-08-25 | F3: 11063 | G3: 6100 | H3: No | I3: N | J3: LE
A4: Larry Gardner | B4: Bronze | C4: 3B | D4: 68 | E4: 2026-06-02 | F4: 40977 | G4: 7890 | H4: No | I4: N | J4: LE
A5: Ian Desmond | B5: Bronze | C5: CF | D5: 64 | E5: 2026-07-07 | F5: 31962 | G5: 5000 | H5: No | I5: N | J5: LE
A6: Jose Lima | B6: Bronze | C6: SP | D6: 69 | E6: 2026-04-13 | F6: 30968 | G6: 26 | H6: No | I6: N | J6: LE
A7: Jose DeLeon | B7: Bronze | C7: SP | D7: 68 | E7: 2026-07-28 | F7: 27171 | G7: 5000 | H7: No | I7: N | J7: LE
A8: Alexi Ogando | B8: Bronze | C8: SP | D8: 66 | E8: 2026-07-06 | F8: 23976 | G8: 1111 | H8: No | I8: N | J8: LE
A9: Shigetoshi Hasegawa | B9: Bronze | C9: CL | D9: 65 | E9: 2026-07-09 | F9: 38218 | G9: 11111 | H9: No | I9: N | J9: LE
A10: Jeff Kent | B10: Silver | C10: 2B | D10: 75 | E10: 2026-07-23 | F10: 41500 | G10: 0 | H10: No | I10: N | J10: LE
A11: Miguel Sano | B11: Silver | C11: 3B | D11: 77 | E11: 2026-07-08 | F11: 70965 | G11: 10000 | H11: No | I11: N | J11: LE
A12: Gus Bell | B12: Silver | C12: CF | D12: 70 | E12: 2026-06-17 | F12: 40218 | G12: 11111 | H12: No | I12: N | J12: LE
A13: Carlos Beltran | B13: Silver | C13: RF | D13: 75 | E13: 2026-07-23 | F13: 30676 | G13: 7777 | H13: No | I13: N | J13: LE
... A22: Doug Fister | B22: Diamond | C22: SP | D22: 98 | E22: 2026-07-28 | F22: 64954 | G22: 53000 | H22: No | I22: N | J22: LE

Sheet Buy over 5000
A1: Name | B1: Tier | C1: Pos | D1: VAL | E1: Released | F1: L10 | G1: BUY | H1: Active | I1: Variant | J1: SubType
A2: CC Sabathia | B2: Perfect | C2: SP | D2: 101 | E2: 2026-07-30 | F2: 397430 | G2: 230000 | H2: Yes | I2: N | J2: BBR
A3: Robb Nen | B3: Perfect | C3: CL | D3: 101 | E3: 2026-07-23 | F3: 196896 | G3: 180100 | H3: Yes | I3: N
A4: Roger Connor | B4: Perfect | C4: 1B | D4: 101 | E4: 2026-08-13 | F4: 205344 | G4: 145000 | H4: Yes | I4: N
A5: Scott Rolen | B5: Perfect | C5: 3B | D5: 101 | E5: 2026-07-30 | F5: 152409 | G5: 128501 | H5: Yes | I5: N | J5: HOF
A6: John McGraw | B6: Perfect | C6: 3B | D6: 101 | E6: 2026-08-13 | F6: 135920 | G6: 110000 | H6: Yes | I6: N
A7: Satchel Paige | B7: Perfect | C7: SP | D7: 100 | E7: 2026-04-15 | F7: 103714 | G7: 95000 | H7: Yes | I7: N
A8: Vida Blue | B8: Perfect | C8: SP | D8: 101 | E8: 2026-06-11 | F8: 115711 | G8: 95000 | H8: Yes | I8: N
A9: Josh Gibson | B9: Perfect | C9: C | D9: 101 | E9: 2026-07-16 | F9: 113200 | G9: 90000 | H9: Yes | I9: N
A10: Phil Rizzuto | B10: Diamond | C10: SS | D10: 99 | E10: 2026-08-19 | F10: 111565 | G10: 90000 | H10: Yes | I10: N | J10: HOF
A11: Johnny Bassler | B11: Diamond | C11: C | D11: 93 | E11: 2026-08-04 | F11: 86653 | G11: 71000 | H11: Yes | I11: N
A12: Eddie Murray | B12: Perfect | C12: 1B | D12: 100 | E12: 2026-06-11 | F12: 82983 | G12: 60001 | H12: No | I12: N | J12: HOF
A13: Rich Gossage | B13: Perfect | C13: CL | D13: 101 | E13: 2026-07-16 | F13: 82446 | G13: 60000 | H13: Yes | I13: N | J13: HOF
A14: Doug Fister | B14: Diamond | C14: SP | D14: 98 | E14: 2026-07-28 | F14: 64954 | G14: 53000 | H14: No | I14: N | J14: LE
A15: Jesse Orosco | B15: Perfect | C15: CL | D15: 100 | E15: 2026-04-20 | F15: 57278 | G15: 49002 | H15: Yes | I15: N
A16: Tom Henke | B16: Perfect | C16: CL | D16: 100 | E16: 2026-07-01 | F16: 48080 | G16: 47500 | H16: Yes | I16: N
A17: Chad Cordero | B17: Silver | C17: CL | D17: 74 | E17: 2026-06-02 | F17: 47087 | G17: 45556 | H17: No | I17: N | J17: LE
A18: Giancarlo Stanton | B18: Perfect | C18: RF | D18: 100 | E18: 2026-03-13 | F18: 54243 | G18: 45000 | H18: No | I18: N
A19: Milt Pappas | B19: Diamond | C19: SP | D19: 96 | E19: 2026-08-19 | F19: 111300 | G19: 44444 | H19: Yes | I19: N
A20: Sam McDowell | B20: Perfect | C20: SP | D20: 100 | E20: 2026-05-07 | F20: 55027 | G20: 43999 | H20: Yes | I20: N | J20: BBR
A21: Harry Steinfeldt | B21: Perfect | C21: 3B | D21: 100 | E21: 2026-03-13 | F21: 54677 | G21: 42500 | H21: No | I21: N
A22: Johnny Vander Meer | B22: Perfect | C22: SP | D22: 100 | E22: 2026-03-13 | F22: 52615 | G22: 42500 | H22: No | I22: N
A23: Jackie Robinson | B23: Perfect | C23: 2B | D23: 100 | E23: 2026-04-16 | F23: 88338 | G23: 40587 | H23: Yes | I23: N
A24: Andrew Miller | B24: Diamond | C24: RP | D24: 99 | E24: 2026-07-30 | F24: 47353 | G24: 37373 | H24: No | I24: N | J24: BBR
A25: Arky Vaughan | B25: Perfect | C25: SS | D25: 101 | E25: 2026-06-25 | F25: 80856 | G25: 36000 | H25: Yes | I25: N
A26: Dizzy Dean | B26: Gold | C26: SP | D26: 88 | E26: 2026-08-04 | F26: 54792 | G26: 35001 | H26: No | I26: N
A27: Kevin Brown | B27: Perfect | C27: SP | D27: 100 | E27: 2026-05-14 | F27: 44675 | G27: 35000 | H27: Yes | I27: N
A28: Jose Altuve | B28: Perfect | C28: 2B | D28: 100 | E28: 2026-07-02 | F28: 62030 | G28: 35000 | H28: No | I28: N | J28: BBR
A29: Tarik Skubal | B29: Perfect | C29: SP | D29: 100 | E29: 2026-03-13 | F29: 37909 | G29: 33333 | H29: No | I29: N
A30: Dave Smith | B30: Perfect | C30: CL | D30: 100 | E30: 2026-03-13 | F30: 59103 | G30: 33333 | H30: No | I30: N
A31: Mel Ott | B31: Perfect | C31: RF | D31: 101 | E31: 2026-07-16 | F31: 102663 | G31: 31000 | H31: Yes | I31: N
A32: Juan Marichal | B32: Perfect | C32: SP | D32: 100 | E32: 2026-03-13 | F32: 91099 | G32: 31000 | H32: No | I32: N | J32: HOF
A33: Solly Hemus | B33: Gold | C33: SS | D33: 83 | E33: 2026-08-09 | F33: 36614 | G33: 30001 | H33: No | I33: N | J33: BBR
A34: Ketel Marte | B34: Perfect | C34: 2B | D34: 100 | E34: 2026-06-04 | F34: 41277 | G34: 29100 | H34: No | I34: N
A35: George Springer | B35: Perfect | C35: CF | D35: 100 | E35: 2026-07-16 | F35: 28229 | G35: 28668 | H35: Yes | I35: N
A36: Frank Robinson | B36: Perfect | C36: RF | D36: 100 | E36: 2026-05-28 | F36: 41114 | G36: 27500 | H36: Yes | I36: N
A37: Cliff Lee | B37: Perfect | C37: SP | D37: 100 | E37: 2026-06-04 | F37: 44442 | G37: 27000 | H37: No | I37: N | J37: BBR
A38: Dolf Luque | B38: Perfect | C38: SP | D38: 100 | E38: 2026-06-04 | F38: 37648 | G38: 25500 | H38: Yes | I38: N | J38: BBR
A39: Camilo Pascual | B39: Perfect | C39: SP | D39: 100 | E39: 2026-03-26 | F39: 112576 | G39: 25001 | H39: No | I39: N
A40: Kitty Bransfield | B40: Bronze | C40: 1B | D40: 63 | E40: 2026-08-07 | F40: 31820 | G40: 25000 | H40: No | I40: N
...

Sheet New LE Wave
A1: Card | B1: Tier | C1: Pos | D1: VAL | E1: Released | F1: SubType | G1: Owned | H1: L10 | I1: Ask | J1: BUY
A2: T4 Ep. 8 - Hall of Fame 3B George Kell DET 1950 | B2: Silver | C2: 3B | D2: 76 | E2: 2026-08-23 | F2: HOF | G2: =FALSE() -> FALSE | H2: 1528 | I2: 1508 | J2: 712
A3: Limited Edition/100 SP Nathan Eovaldi MIA 2013 | B3: Iron | C3: SP | D3: 59 | E3: 2026-08-25 | F3: LE | G3: =TRUE() -> TRUE | H3: 11063 | I3: 10999 | J3: 6100
A4: Limited Edition/56 SP Bill Pulsipher NYM 1995 | B4: Iron | C4: SP | D4: 56 | E4: 2026-08-25 | F4: LE | G4: =FALSE() -> FALSE | H4: 29582 | I4: 77777 | J4: 29582
A5: Limited Edition/50 RP Jonny Venters TB 2018 | B5: Iron | C5: RP | D5: 50 | E5: 2026-08-24 | F5: LE | G5: =FALSE() -> FALSE | H5: 30328 | I5: 80000 | J5: 30328
A6: Limited Edition/47 C Taylor Teagarden TEX 2008 | B6: Iron | C6: C | D6: 44 | E6: 2026-08-24 | F6: LE | G6: =FALSE() -> FALSE | H6: 19352 | I6: 39999 | J6: 13865
A7: Limited Edition/60 SP Rubby De La Rosa LAD 2011 | B7: Iron | C7: SP | D7: 44 | E7: 2026-08-25 | F7: LE | G7: =FALSE() -> FALSE | H7: 13381 | I7: 19998 | J7: 14567
A8: Limited Edition/52 RP Jack Leathersich NYM 2015 | B8: Iron | C8: RP | D8: 41 | E8: 2026-08-24 | F8: LE | G8: =FALSE() -> FALSE | H8: 60999 | I8: 74668 | J8: 31000
A9: Limited Edition/81 SP Brandon Beachy ATL 2012 | B9: Bronze | C9: SP | D9: 67 | E9: 2026-08-24 | F9: LE | G9: =FALSE() -> FALSE | H9: 29252 | I9: 79999 | J9: 27000
A10: Limited Edition/79 SP Danny Salazar CLE 2015 | B10: Bronze | C10: SP | D10: 66 | E10: 2026-08-24 | F10: LE | G10: =FALSE() -> FALSE | H10: 13051 | I10: 12500 | J10: 2100
A11: Limited Edition/44 RP Bill Bray CIN 2011 | B11: Bronze | C11: RP | D11: 64 | E11: 2026-08-25 | F11: LE | G11: =FALSE() -> FALSE | H11: 34718 | I11: 0 | J11: 33334
A12: Limited Edition/63 SP Jarrod Parker ATH 2012 | B12: Bronze | C12: SP | D12: 63 | E12: 2026-08-25 | F12: LE | G12: =FALSE() -> FALSE | H12: 25632 | I12: 0 | J12: 23000
A13: Limited Edition/122 CF Aaron Hicks NYY 2020 | B13: Bronze | C13: CF | D13: 63 | E13: 2026-08-25 | F13: LE | G13: =FALSE() -> FALSE | H13: 6671 | I13: 6499 | J13: 2750
A14: Limited Edition/100 SP Jacob deGrom NYM 2014 | B14: Silver | C14: SP | D14: 79 | E14: 2026-08-25 | F14: LE | G14: =FALSE() -> FALSE | H14: 73805 | I14: 93775 | J14: 68000
A15: Limited Edition/86 SP Daniel Hudson ARI 2011 | B15: Silver | C15: SP | D15: 76 | E15: 2026-08-25 | F15: LE | G15: =FALSE() -> FALSE | H15: 38574 | I15: 34999 | J15: 20007
... A24: Limited Edition/34 CL Jason Isringhausen ATH 2001 | B24: Perfect | C24: CL | D24: 101 | E24: 2026-08-24 | F24: LE | G24: =FALSE() -> FALSE | H24: 323666 | I24: 254999 | J24: 99999
A25: T4 Ep. 8 - Historical All-Star SS Vern Stephens BOS 1950 | B25: Iron | C25: SS | D25: 58 | E25: 2026-08-23 | G25: =TRUE() -> TRUE | H25: 171 | I25: 183 | J25: 13
A26: T4 Ep. 8 - Unsung Heroes 2B Daryl Spencer SF 1959 | B26: Iron | C26: 2B | D26: 57 | E26: 2026-08-23 | G26: =TRUE() -> TRUE | H26: 160 | I26: 123 | J26: 28
A27: In Memoriam - Snapshot SP Tommy John CWS 1965 | B27: Iron | C27: SP | D27: 56 | E27: 2026-08-24 | G27: =TRUE() -> TRUE | H27: 216 | I27: 181 | J27: 13
A28: T4 Ep. 8 - Veteran Presence LF Ted Williams BOS 1959 | B28: Iron | C28: LF | D28: 54 | E28: 2026-08-23 | G28: =TRUE() -> TRUE | H28: 114 | I28: 111 | J28: 9
A29: T4 Ep. 8 - Veteran Presence RP Mike Garcia CLE 1959 | B29: Iron | C29: RP | D29: 49 | E29: 2026-08-23 | G29: =TRUE() -> TRUE | H29: 115 | I29: 110 | J29: 12
A30: T4 Ep. 8 - Unsung Heroes 3B Hal Smith KC1 1959 | B30: Iron | C30: 3B | D30: 48 | E30: 2026-08-23 | G30: =FALSE() -> FALSE | H30: 124 | I30: 144 | J30: 13
A31: T4 Ep. 8 - All-Time Legend RP Bob Ross WS1 1951 | B31: Iron | C31: RP | D31: 41 | E31: 2026-08-23 | G31: =TRUE() -> TRUE | H31: 91 | I31: 87 | J31: 9
A32: T4 Ep. 8 - Snapshot C Ed Bailey CIN 1959 | B32: Bronze | C32: C | D32: 69 | E32: 2026-08-23 | G32: =FALSE() -> FALSE | H32: 248 | I32: 219 | J32: 30
A33: T4 Ep. 8 - Unsung Heroes LF Wes Covington ML1 1958 | B33: Bronze | C33: LF | D33: 67 | E33: 2026-08-23 | G33: =TRUE() -> TRUE | H33: 181 | I33: 173 | J33: 30
A34: T4 Ep. 8 - Snapshot RP Nelson Chittum BOS 1959 | B34: Bronze | C34: RP | D34: 61 | E34: 2026-08-23 | G34: =TRUE() -> TRUE | H34: 330 | I34: 312 | J34: 29
A35: T4 Ep. 8 - Snapshot RF Jackie Jensen BOS 1959 | B35: Silver | C35: RF | D35: 79 | E35: 2026-08-23 | G35: =FALSE() -> FALSE | H35: 1487 | I35: 1708 | J35: 444
A36: T4 Ep. 8 - Historical All-Star SP Joe Nuxhall CIN 1955 | B36: Silver | C36: SP | D36: 71 | E36: 2026-08-23 | G36: =TRUE() -> TRUE | H36: 738 | I36: 1000 | J36: 120
A37: T4 Ep. 8 - Snapshot SP Art Ditmar NYY 1959 | B37: Gold | C37: SP | D37: 82 | E37: 2026-08-23 | G37: =FALSE() -> FALSE | H37: 11498 | I37: 20200 | J37: 3000
A38: In Memoriam - Historical All-Star SP Tommy John NYY 1979 | B38: Diamond | C38: SP | D38: 92 | E38: 2026-08-24 | G38: =FALSE() -> FALSE | H38: 28223 | I38: 60000 | J38: 18339
